
Traceback (most recent call last):
  File "tests/exceptions/backtrace/chained_expression_indirect.py", line 10, in a
    1 / 0
ZeroDivisionError: division by zero

During handling of the above exception, another exception occurred:

Traceback (most recent call last):
> File "tests/exceptions/backtrace/chained_expression_indirect.py", line 20, in <module>
    b()
  File "tests/exceptions/backtrace/chained_expression_indirect.py", line 17, in b
    a()
  File "tests/exceptions/backtrace/chained_expression_indirect.py", line 12, in a
    raise ValueError("NOK")
ValueError: NOK

Traceback (most recent call last):
  File "tests/exceptions/backtrace/chained_expression_indirect.py", line 10, in a
    1 / 0
ZeroDivisionError: division by zero

During handling of the above exception, another exception occurred:

Traceback (most recent call last):
> File "tests/exceptions/backtrace/chained_expression_indirect.py", line 23, in <module>
    a()
  File "tests/exceptions/backtrace/chained_expression_indirect.py", line 12, in a
    raise ValueError("NOK")
ValueError: NOK

Traceback (most recent call last):
  File "tests/exceptions/backtrace/chained_expression_indirect.py", line 10, in a
    1 / 0
ZeroDivisionError: division by zero

During handling of the above exception, another exception occurred:

Traceback (most recent call last):
> File "tests/exceptions/backtrace/chained_expression_indirect.py", line 26, in <module>
    a()
  File "tests/exceptions/backtrace/chained_expression_indirect.py", line 12, in a
    raise ValueError("NOK")
ValueError: NOK
