
Traceback (most recent call last):

  File "tests/exceptions/backtrace/suppressed_expression_indirect.py", line 14, in b
    a(1, 0)
    └ <function a at 0xDEADBEEF>

  File "tests/exceptions/backtrace/suppressed_expression_indirect.py", line 9, in a
    x / y
    │   └ 0
    └ 1

ZeroDivisionError: division by zero


The above exception was the direct cause of the following exception:


Traceback (most recent call last):

> File "tests/exceptions/backtrace/suppressed_expression_indirect.py", line 28, in <module>
    c_decorated()
    └ <function c_decorated at 0xDEADBEEF>

  File "tests/exceptions/backtrace/suppressed_expression_indirect.py", line 21, in c_decorated
    b()
    └ <function b at 0xDEADBEEF>

  File "tests/exceptions/backtrace/suppressed_expression_indirect.py", line 16, in b
    raise ValueError("NOK") from e
          └ <class 'ValueError'>

ValueError: NOK

Traceback (most recent call last):

  File "tests/exceptions/backtrace/suppressed_expression_indirect.py", line 14, in b
    a(1, 0)
    └ <function a at 0xDEADBEEF>

  File "tests/exceptions/backtrace/suppressed_expression_indirect.py", line 9, in a
    x / y
    │   └ 0
    └ 1

ZeroDivisionError: division by zero


The above exception was the direct cause of the following exception:


Traceback (most recent call last):

> File "tests/exceptions/backtrace/suppressed_expression_indirect.py", line 31, in <module>
    c_not_decorated()
    └ <function c_not_decorated at 0xDEADBEEF>

  File "tests/exceptions/backtrace/suppressed_expression_indirect.py", line 25, in c_not_decorated
    b()
    └ <function b at 0xDEADBEEF>

  File "tests/exceptions/backtrace/suppressed_expression_indirect.py", line 16, in b
    raise ValueError("NOK") from e
          └ <class 'ValueError'>

ValueError: NOK

Traceback (most recent call last):

  File "tests/exceptions/backtrace/suppressed_expression_indirect.py", line 14, in b
    a(1, 0)
    └ <function a at 0xDEADBEEF>

  File "tests/exceptions/backtrace/suppressed_expression_indirect.py", line 9, in a
    x / y
    │   └ 0
    └ 1

ZeroDivisionError: division by zero


The above exception was the direct cause of the following exception:


Traceback (most recent call last):

> File "tests/exceptions/backtrace/suppressed_expression_indirect.py", line 34, in <module>
    c_not_decorated()
    └ <function c_not_decorated at 0xDEADBEEF>

  File "tests/exceptions/backtrace/suppressed_expression_indirect.py", line 25, in c_not_decorated
    b()
    └ <function b at 0xDEADBEEF>

  File "tests/exceptions/backtrace/suppressed_expression_indirect.py", line 16, in b
    raise ValueError("NOK") from e
          └ <class 'ValueError'>

ValueError: NOK
