
Traceback (most recent call last):

  File "tests/exceptions/backtrace/suppressed_expression_direct.py", line 15, in b_decorated
    a(1, 0)
    └ <function a at 0xDEADBEEF>

  File "tests/exceptions/backtrace/suppressed_expression_direct.py", line 9, in a
    x / y
    │   └ 0
    └ 1

ZeroDivisionError: division by zero


The above exception was the direct cause of the following exception:


Traceback (most recent call last):

  File "tests/exceptions/backtrace/suppressed_expression_direct.py", line 43, in <module>
    c_decorator()
    └ <function c_decorator at 0xDEADBEEF>

> File "tests/exceptions/backtrace/suppressed_expression_direct.py", line 28, in c_decorator
    b_decorated()
    └ <function b_decorated at 0xDEADBEEF>

  File "tests/exceptions/backtrace/suppressed_expression_direct.py", line 17, in b_decorated
    raise ValueError("NOK") from e
          └ <class 'ValueError'>

ValueError: NOK

Traceback (most recent call last):

  File "tests/exceptions/backtrace/suppressed_expression_direct.py", line 22, in b_not_decorated
    a(1, 0)
    └ <function a at 0xDEADBEEF>

  File "tests/exceptions/backtrace/suppressed_expression_direct.py", line 9, in a
    x / y
    │   └ 0
    └ 1

ZeroDivisionError: division by zero


The above exception was the direct cause of the following exception:


Traceback (most recent call last):

  File "tests/exceptions/backtrace/suppressed_expression_direct.py", line 44, in <module>
    c_context_manager()
    └ <function c_context_manager at 0xDEADBEEF>

> File "tests/exceptions/backtrace/suppressed_expression_direct.py", line 33, in c_context_manager
    b_not_decorated()
    └ <function b_not_decorated at 0xDEADBEEF>

  File "tests/exceptions/backtrace/suppressed_expression_direct.py", line 24, in b_not_decorated
    raise ValueError("NOK") from e
          └ <class 'ValueError'>

ValueError: NOK

Traceback (most recent call last):

  File "tests/exceptions/backtrace/suppressed_expression_direct.py", line 22, in b_not_decorated
    a(1, 0)
    └ <function a at 0xDEADBEEF>

  File "tests/exceptions/backtrace/suppressed_expression_direct.py", line 9, in a
    x / y
    │   └ 0
    └ 1

ZeroDivisionError: division by zero


The above exception was the direct cause of the following exception:


Traceback (most recent call last):

  File "tests/exceptions/backtrace/suppressed_expression_direct.py", line 45, in <module>
    c_explicit()
    └ <function c_explicit at 0xDEADBEEF>

> File "tests/exceptions/backtrace/suppressed_expression_direct.py", line 38, in c_explicit
    b_not_decorated()
    └ <function b_not_decorated at 0xDEADBEEF>

  File "tests/exceptions/backtrace/suppressed_expression_direct.py", line 24, in b_not_decorated
    raise ValueError("NOK") from e
          └ <class 'ValueError'>

ValueError: NOK
